Workbook

Sheet 종합등위분류1
B1: 초 등 부 종 합 등 위 | F1: 중 등 부 종 합 등 위 | K1: 전 체 종 합 등 위
A2: 정렬 | B2: 등위 | C2: 소속 | D2: 기록 | E2: 평균시속 | F2: 등위 | G2: 소속 | H2: 기록 | I2: 평균시속 | J2: 순 | K2: 종합등위 | L2: 소속 | M2: 종합기록 | N2: 평균시속
A3: 1 | B3: =[1]종합등위!$B3 -> 1 | C3: =[1]종합등위!$C3 -> 영천 | D3: =[1]종합등위!$K3 -> 0.041435185 | E3: =[1]종합등위!$M3 -> 15.888268 | F3: =[2]종합등위!$B3 -> 1 | G3: =[2]종합등위!$C3 -> 구미 | H3: =[2]종합등위!$J3 -> 0.039328704 | I3: =[2]종합등위!$L3 -> 16.739258 | J3: 1 | K3: =IF(M3=0,"",RANK(M3,$M$3:$M$25,2)&IF(COUNTIF($M$3:$M$25,M3)>=2,"("&COUNTIF($M$3:$M$25,M3)&")","")) -> 12 | L3: 포항 | M3: =IF(ISERROR(VLOOKUP(L3,$C$3:$D$25,2,FALSE)),0,VLOOKUP(L3,$C$3:$D$25,2,FALSE))+IF(ISERROR(VLOOKUP(L3,$G$3:$H$25,2,FALSE)),0,VLOOKUP(L3,$G$3:$H$25,2,FALSE)) -> 0.091782406 | N3: =IF(M3=0,"",$M$27/M3/24) -> 13.029004
A4: 2 | B4: =[1]종합등위!$B4 -> 2 | C4: =[1]종합등위!$C4 -> 경주 | D4: =[1]종합등위!$K4 -> 0.042418981 | E4: =[1]종합등위!$M4 -> 15.519782 | F4: =[2]종합등위!$B4 -> 2 | G4: =[2]종합등위!$C4 -> 영천 | H4: =[2]종합등위!$J4 -> 0.040081019 | I4: =[2]종합등위!$L4 -> 16.425065 | J4: 2 | K4: =IF(M4=0,"",RANK(M4,$M$3:$M$25,2)&IF(COUNTIF($M$3:$M$25,M4)>=2,"("&COUNTIF($M$3:$M$25,M4)&")","")) -> 3 | L4: 경주 | M4: =IF(ISERROR(VLOOKUP(L4,$C$3:$D$25,2,FALSE)),0,VLOOKUP(L4,$C$3:$D$25,2,FALSE))+IF(ISERROR(VLOOKUP(L4,$G$3:$H$25,2,FALSE)),0,VLOOKUP(L4,$G$3:$H$25,2,FALSE)) -> 0.084340278 | N4: =IF(M4=0,"",$M$27/M4/24) -> 14.178674
A5: 3 | B5: =[1]종합등위!$B5 -> 3 | C5: =[1]종합등위!$C5 -> 문경 | D5: =[1]종합등위!$K5 -> 0.043125001 | E5: =[1]종합등위!$M5 -> 15.2657 | F5: =[2]종합등위!$B5 -> 3 | G5: =[2]종합등위!$C5 -> 문경 | H5: =[2]종합등위!$J5 -> 0.040451388 | I5: =[2]종합등위!$L5 -> 16.274678 | J5: 3 | K5: =IF(M5=0,"",RANK(M5,$M$3:$M$25,2)&IF(COUNTIF($M$3:$M$25,M5)>=2,"("&COUNTIF($M$3:$M$25,M5)&")","")) -> 6 | L5: 김천 | M5: =IF(ISERROR(VLOOKUP(L5,$C$3:$D$25,2,FALSE)),0,VLOOKUP(L5,$C$3:$D$25,2,FALSE))+IF(ISERROR(VLOOKUP(L5,$G$3:$H$25,2,FALSE)),0,VLOOKUP(L5,$G$3:$H$25,2,FALSE)) -> 0.086770833 | N5: =IF(M5=0,"",$M$27/M5/24) -> 13.781513
A6: 4 | B6: =[1]종합등위!$B6 -> 4 | C6: =[1]종합등위!$C6 -> 안동 | D6: =[1]종합등위!$K6 -> 0.043379628 | E6: =[1]종합등위!$M6 -> 15.176095 | F6: =[2]종합등위!$B6 -> 4 | G6: =[2]종합등위!$C6 -> 칠곡 | H6: =[2]종합등위!$J6 -> 0.041446759 | I6: =[2]종합등위!$L6 -> 15.883832 | J6: 4 | K6: =IF(M6=0,"",RANK(M6,$M$3:$M$25,2)&IF(COUNTIF($M$3:$M$25,M6)>=2,"("&COUNTIF($M$3:$M$25,M6)&")","")) -> 7 | L6: 안동 | M6: =IF(ISERROR(VLOOKUP(L6,$C$3:$D$25,2,FALSE)),0,VLOOKUP(L6,$C$3:$D$25,2,FALSE))+IF(ISERROR(VLOOKUP(L6,$G$3:$H$25,2,FALSE)),0,VLOOKUP(L6,$G$3:$H$25,2,FALSE)) -> 0.086921295 | N6: =IF(M6=0,"",$M$27/M6/24) -> 13.757657 | O6: 초등부 바로가기
A7: 5 | B7: =[1]종합등위!$B7 -> 5 | C7: =[1]종합등위!$C7 -> 경산 | D7: =[1]종합등위!$K7 -> 0.044155093 | E7: =[1]종합등위!$M7 -> 14.909568 | F7: =[2]종합등위!$B7 -> 5 | G7: =[2]종합등위!$C7 -> 경주 | H7: =[2]종합등위!$J7 -> 0.041921298 | I7: =[2]종합등위!$L7 -> 15.70403 | J7: 5 | K7: =IF(M7=0,"",RANK(M7,$M$3:$M$25,2)&IF(COUNTIF($M$3:$M$25,M7)>=2,"("&COUNTIF($M$3:$M$25,M7)&")","")) -> 4 | L7: 구미 | M7: =IF(ISERROR(VLOOKUP(L7,$C$3:$D$25,2,FALSE)),0,VLOOKUP(L7,$C$3:$D$25,2,FALSE))+IF(ISERROR(VLOOKUP(L7,$G$3:$H$25,2,FALSE)),0,VLOOKUP(L7,$G$3:$H$25,2,FALSE)) -> 0.08494213 | N7: =IF(M7=0,"",$M$27/M7/24) -> 14.078212 | O7: 중등부 바로가기
A8: 6 | B8: =[1]종합등위!$B8 -> 6 | C8: =[1]종합등위!$C8 -> 고령 | D8: =[1]종합등위!$K8 -> 0.044224537 | E8: =[1]종합등위!$M8 -> 14.886155 | F8: =[2]종합등위!$B8 -> 6 | G8: =[2]종합등위!$C8 -> 김천 | H8: =[2]종합등위!$J8 -> 0.042164352 | I8: =[2]종합등위!$L8 -> 15.613505 | J8: 6 | K8: =IF(M8=0,"",RANK(M8,$M$3:$M$25,2)&IF(COUNTIF($M$3:$M$25,M8)>=2,"("&COUNTIF($M$3:$M$25,M8)&")","")) -> 8 | L8: 영주 | M8: =IF(ISERROR(VLOOKUP(L8,$C$3:$D$25,2,FALSE)),0,VLOOKUP(L8,$C$3:$D$25,2,FALSE))+IF(ISERROR(VLOOKUP(L8,$G$3:$H$25,2,FALSE)),0,VLOOKUP(L8,$G$3:$H$25,2,FALSE)) -> 0.087893517 | N8: =IF(M8=0,"",$M$27/M8/24) -> 13.605478
A9: 7 | B9: =[1]종합등위!$B9 -> 7 | C9: =[1]종합등위!$C9 -> 상주 | D9: =[1]종합등위!$K9 -> 0.04443287 | E9: =[1]종합등위!$M9 -> 14.816358 | F9: =[2]종합등위!$B9 -> 7 | G9: =[2]종합등위!$C9 -> 경산 | H9: =[2]종합등위!$J9 -> 0.042465278 | I9: =[2]종합등위!$L9 -> 15.502862 | J9: 7 | K9: =IF(M9=0,"",RANK(M9,$M$3:$M$25,2)&IF(COUNTIF($M$3:$M$25,M9)>=2,"("&COUNTIF($M$3:$M$25,M9)&")","")) -> 1 | L9: 영천 | M9: =IF(ISERROR(VLOOKUP(L9,$C$3:$D$25,2,FALSE)),0,VLOOKUP(L9,$C$3:$D$25,2,FALSE))+IF(ISERROR(VLOOKUP(L9,$G$3:$H$25,2,FALSE)),0,VLOOKUP(L9,$G$3:$H$25,2,FALSE)) -> 0.081516204 | N9: =IF(M9=0,"",$M$27/M9/24) -> 14.669885
A10: 8 | B10: =[1]종합등위!$B10 -> 8 | C10: =[1]종합등위!$C10 -> 김천 | D10: =[1]종합등위!$K10 -> 0.044606481 | E10: =[1]종합등위!$M10 -> 14.758693 | F10: =[2]종합등위!$B10 -> 8 | G10: =[2]종합등위!$C10 -> 영주 | H10: =[2]종합등위!$J10 -> 0.043090277 | I10: =[2]종합등위!$L10 -> 15.278002 | J10: 8 | K10: =IF(M10=0,"",RANK(M10,$M$3:$M$25,2)&IF(COUNTIF($M$3:$M$25,M10)>=2,"("&COUNTIF($M$3:$M$25,M10)&")","")) -> 9 | L10: 상주 | M10: =IF(ISERROR(VLOOKUP(L10,$C$3:$D$25,2,FALSE)),0,VLOOKUP(L10,$C$3:$D$25,2,FALSE))+IF(ISERROR(VLOOKUP(L10,$G$3:$H$25,2,FALSE)),0,VLOOKUP(L10,$G$3:$H$25,2,FALSE)) -> 0.088877315 | N10: =IF(M10=0,"",$M$27/M10/24) -> 13.454877
A11: 9 | B11: =[1]종합등위!$B11 -> 9 | C11: =[1]종합등위!$C11 -> 영주 | D11: =[1]종합등위!$K11 -> 0.04480324 | E11: =[1]종합등위!$M11 -> 14.693878 | F11: =[2]종합등위!$B11 -> 9 | G11: =[2]종합등위!$C11 -> 포항 | H11: =[2]종합등위!$J11 -> 0.043344907 | I11: =[2]종합등위!$L11 -> 15.188251 | J11: 9 | K11: =IF(M11=0,"",RANK(M11,$M$3:$M$25,2)&IF(COUNTIF($M$3:$M$25,M11)>=2,"("&COUNTIF($M$3:$M$25,M11)&")","")) -> 2 | L11: 문경 | M11: =IF(ISERROR(VLOOKUP(L11,$C$3:$D$25,2,FALSE)),0,VLOOKUP(L11,$C$3:$D$25,2,FALSE))+IF(ISERROR(VLOOKUP(L11,$G$3:$H$25,2,FALSE)),0,VLOOKUP(L11,$G$3:$H$25,2,FALSE)) -> 0.083576389 | N11: =IF(M11=0,"",$M$27/M11/24) -> 14.308268
A12: 10 | B12: =[1]종합등위!$B12 -> 10 | C12: =[1]종합등위!$C12 -> 구미 | D12: =[1]종합등위!$K12 -> 0.045613426 | E12: =[1]종합등위!$M12 -> 14.432885 | F12: =[2]종합등위!$B12 -> 10 | G12: =[2]종합등위!$C12 -> 안동 | H12: =[2]종합등위!$J12 -> 0.043541667 | I12: =[2]종합등위!$L12 -> 15.119617 | J12: 10 | K12: =IF(M12=0,"",RANK(M12,$M$3:$M$25,2)&IF(COUNTIF($M$3:$M$25,M12)>=2,"("&COUNTIF($M$3:$M$25,M12)&")","")) -> 5 | L12: 경산 | M12: =IF(ISERROR(VLOOKUP(L12,$C$3:$D$25,2,FALSE)),0,VLOOKUP(L12,$C$3:$D$25,2,FALSE))+IF(ISERROR(VLOOKUP(L12,$G$3:$H$25,2,FALSE)),0,VLOOKUP(L12,$G$3:$H$25,2,FALSE)) -> 0.08662037 | N12: =IF(M12=0,"",$M$27/M12/24) -> 13.805452
A13: 11 | B13: =[1]종합등위!$B13 -> 11 | C13: =[1]종합등위!$C13 -> 칠곡 | D13: =[1]종합등위!$K13 -> 0.047997685 | E13: =[1]종합등위!$M13 -> 13.715939 | F13: =[2]종합등위!$B13 -> 11 | G13: =[2]종합등위!$C13 -> 상주 | H13: =[2]종합등위!$J13 -> 0.044444445 | I13: =[2]종합등위!$L13 -> 14.8125 | J13: 11 | K13: =IF(M13=0,"",RANK(M13,$M$3:$M$25,2)&IF(COUNTIF($M$3:$M$25,M13)>=2,"("&COUNTIF($M$3:$M$25,M13)&")","")) -> 16 | L13: 군위 | M13: =IF(ISERROR(VLOOKUP(L13,$C$3:$D$25,2,FALSE)),0,VLOOKUP(L13,$C$3:$D$25,2,FALSE))+IF(ISERROR(VLOOKUP(L13,$G$3:$H$25,2,FALSE)),0,VLOOKUP(L13,$G$3:$H$25,2,FALSE)) -> 0.10597222 | N13: =IF(M13=0,"",$M$27/M13/24) -> 11.284404
A14: 12 | B14: =[1]종합등위!$B14 -> 12 | C14: =[1]종합등위!$C14 -> 포항 | D14: =[1]종합등위!$K14 -> 0.048437499 | E14: =[1]종합등위!$M14 -> 13.591398 | F14: =[2]종합등위!$B14 -> 12 | G14: =[2]종합등위!$C14 -> 고령 | H14: =[2]종합등위!$J14 -> 0.045173612 | I14: =[2]종합등위!$L14 -> 14.573405 | J14: 12 | K14: =IF(M14=0,"",RANK(M14,$M$3:$M$25,2)&IF(COUNTIF($M$3:$M$25,M14)>=2,"("&COUNTIF($M$3:$M$25,M14)&")","")) -> 19 | L14: 의성 | M14: =IF(ISERROR(VLOOKUP(L14,$C$3:$D$25,2,FALSE)),0,VLOOKUP(L14,$C$3:$D$25,2,FALSE))+IF(ISERROR(VLOOKUP(L14,$G$3:$H$25,2,FALSE)),0,VLOOKUP(L14,$G$3:$H$25,2,FALSE)) -> 0.1074537 | N14: =IF(M14=0,"",$M$27/M14/24) -> 11.128824
A15: 13 | B15: =[1]종합등위!$B15 -> 13 | C15: =[1]종합등위!$C15 -> 영덕 | D15: =[1]종합등위!$K15 -> 0.048645833 | E15: =[1]종합등위!$M15 -> 13.533191 | F15: =[2]종합등위!$B15 -> 13 | G15: =[2]종합등위!$C15 -> 영덕 | H15: =[2]종합등위!$J15 -> 0.047372685 | I15: =[2]종합등위!$L15 -> 13.896897 | J15: 13 | K15: =IF(M15=0,"",RANK(M15,$M$3:$M$25,2)&IF(COUNTIF($M$3:$M$25,M15)>=2,"("&COUNTIF($M$3:$M$25,M15)&")","")) -> 22 | L15: 청송 | M15: =IF(ISERROR(VLOOKUP(L15,$C$3:$D$25,2,FALSE)),0,VLOOKUP(L15,$C$3:$D$25,2,FALSE))+IF(ISERROR(VLOOKUP(L15,$G$3:$H$25,2,FALSE)),0,VLOOKUP(L15,$G$3:$H$25,2,FALSE)) -> 0.1150463 | N15: =IF(M15=0,"",$M$27/M15/24) -> 10.394366
A16: 14 | B16: =[1]종합등위!$B16 -> 14 | C16: =[1]종합등위!$C16 -> 예천 | D16: =[1]종합등위!$K16 -> 0.049305557 | E16: =[1]종합등위!$M16 -> 13.352112 | F16: =[2]종합등위!$B16 -> 14 | G16: =[2]종합등위!$C16 -> 봉화 | H16: =[2]종합등위!$J16 -> 0.050486112 | I16: =[2]종합등위!$L16 -> 13.03989 | J16: 14 | K16: =IF(M16=0,"",RANK(M16,$M$3:$M$25,2)&IF(COUNTIF($M$3:$M$25,M16)>=2,"("&COUNTIF($M$3:$M$25,M16)&")","")) -> 20 | L16: 영양 | M16: =IF(ISERROR(VLOOKUP(L16,$C$3:$D$25,2,FALSE)),0,VLOOKUP(L16,$C$3:$D$25,2,FALSE))+IF(ISERROR(VLOOKUP(L16,$G$3:$H$25,2,FALSE)),0,VLOOKUP(L16,$G$3:$H$25,2,FALSE)) -> 0.11070602 | N16: =IF(M16=0,"",$M$27/M16/24) -> 10.801882
A17: 15 | B17: =[1]종합등위!$B17 -> 15 | C17: =[1]종합등위!$C17 -> 봉화 | D17: =[1]종합등위!$K17 -> 0.05074074 | E17: =[1]종합등위!$M17 -> 12.974453 | F17: =[2]종합등위!$B17 -> 15 | G17: =[2]종합등위!$C17 -> 의성 | H17: =[2]종합등위!$J17 -> 0.050833333 | I17: =[2]종합등위!$L17 -> 12.95082 | J17: 15 | K17: =IF(M17=0,"",RANK(M17,$M$3:$M$25,2)&IF(COUNTIF($M$3:$M$25,M17)>=2,"("&COUNTIF($M$3:$M$25,M17)&")","")) -> 13 | L17: 영덕 | M17: =IF(ISERROR(VLOOKUP(L17,$C$3:$D$25,2,FALSE)),0,VLOOKUP(L17,$C$3:$D$25,2,FALSE))+IF(ISERROR(VLOOKUP(L17,$G$3:$H$25,2,FALSE)),0,VLOOKUP(L17,$G$3:$H$25,2,FALSE)) -> 0.096018519 | N17: =IF(M17=0,"",$M$27/M17/24) -> 12.454195
A18: 16 | B18: =[1]종합등위!$B18 -> 16 | C18: =[1]종합등위!$C18 -> 청도 | D18: =[1]종합등위!$K18 -> 0.05136574 | E18: =[1]종합등위!$M18 -> 12.816584 | F18: =[2]종합등위!$B18 -> 16 | G18: =[2]종합등위!$C18 -> 예천 | H18: =[2]종합등위!$J18 -> 0.050949073 | I18: =[2]종합등위!$L18 -> 12.9214 | J18: 16 | K18: =IF(M18=0,"",RANK(M18,$M$3:$M$25,2)&IF(COUNTIF($M$3:$M$25,M18)>=2,"("&COUNTIF($M$3:$M$25,M18)&")","")) -> 17 | L18: 청도 | M18: =IF(ISERROR(VLOOKUP(L18,$C$3:$D$25,2,FALSE)),0,VLOOKUP(L18,$C$3:$D$25,2,FALSE))+IF(ISERROR(VLOOKUP(L18,$G$3:$H$25,2,FALSE)),0,VLOOKUP(L18,$G$3:$H$25,2,FALSE)) -> 0.1062037 | N18: =IF(M18=0,"",$M$27/M18/24) -> 11.259808
A19: 17 | B19: =[1]종합등위!$B19 -> 17 | C19: =[1]종합등위!$C19 -> 영양 | D19: =[1]종합등위!$K19 -> 0.053055556 | E19: =[1]종합등위!$M19 -> 12.408377 | F19: =[2]종합등위!$B19 -> 17 | G19: =[2]종합등위!$C19 -> 울진 | H19: =[2]종합등위!$J19 -> 0.051701389 | I19: =[2]종합등위!$L19 -> 12.733378 | J19: 17 | K19: =IF(M19=0,"",RANK(M19,$M$3:$M$25,2)&IF(COUNTIF($M$3:$M$25,M19)>=2,"("&COUNTIF($M$3:$M$25,M19)&")","")) -> 10 | L19: 고령 | M19: =IF(ISERROR(VLOOKUP(L19,$C$3:$D$25,2,FALSE)),0,VLOOKUP(L19,$C$3:$D$25,2,FALSE))+IF(ISERROR(VLOOKUP(L19,$G$3:$H$25,2,FALSE)),0,VLOOKUP(L19,$G$3:$H$25,2,FALSE)) -> 0.089398149 | N19: =IF(M19=0,"",$M$27/M19/24) -> 13.376489
... A24: 22 | B24: =[1]종합등위!$B24 -> 22 | C24: =[1]종합등위!$C24 -> 청송 | D24: =[1]종합등위!$K24 -> 0.057083334 | E24: =[1]종합등위!$M24 -> 11.532847 | F24: =[2]종합등위!$B24 -> 22 | G24: =[2]종합등위!$C24 -> 성주 | H24: =[2]종합등위!$J24 -> 0.058865741 | I24: =[2]종합등위!$L24 -> 11.183641 | J24: 22 | K24: =IF(M24=0,"",RANK(M24,$M$3:$M$25,2)&IF(COUNTIF($M$3:$M$25,M24)>=2,"("&COUNTIF($M$3:$M$25,M24)&")","")) -> 18 | L24: 울진 | M24: =IF(ISERROR(VLOOKUP(L24,$C$3:$D$25,2,FALSE)),0,VLOOKUP(L24,$C$3:$D$25,2,FALSE))+IF(ISERROR(VLOOKUP(L24,$G$3:$H$25,2,FALSE)),0,VLOOKUP(L24,$G$3:$H$25,2,FALSE)) -> 0.10657407 | N24: =IF(M24=0,"",$M$27/M24/24) -> 11.220678
A25: 23 | J25: 23
B27: 초등구간거리 | D27: =[3]초등부자료입력!$C$1 -> 14.35 | F27: 중등구간거리 | H27: =[4]중등부자료입력!$C$1 -> 14.35 | K27: 총구간거리 | M27: =D27+H27 -> 28.7
B30: 1.복사할 면 시트보호후 전체를 복사 함 2.붙여넣을 면에 " 붙여넣기" 선택

Sheet 도교육청요청자료1
B1: 초 등 부 종 합 등 위 | F1: 중 등 부 종 합 등 위 | K1: 전 체 종 합 등 위
A2: 순 | B2: 등위 | C2: 소속 | D2: 기록 | E2: 평균시속 | F2: 등위 | G2: 소속 | H2: 기록 | I2: 평균시속 | J2: 순 | K2: 종합등위 | L2: 소속 | M2: 종합기록 | N2: 평균시속
A3: 1 | B3: 1 | C3: 영천 | D3: 0.038553241 | E3: 15.508856 | F3: 1 | G3: 구미 | H3: 0.038229167 | I3: 15.640327 | J3: 5 | K3: 1 | L3: 구미 | M3: 0.078148148 | N3: 15.302133
A4: 2 | B4: 2 | C4: 고령 | D4: 0.03974537 | E4: 15.043681 | F4: 2 | G4: 상주 | H4: 0.038761574 | I4: 15.4255 | J4: 6 | K4: 2 | L4: 영주 | M4: 0.079722222 | N4: 15
A5: 3 | B5: 3 | C5: 영주 | D5: 0.039826389 | E5: 15.013078 | F5: 3 | G5: 칠곡 | H5: 0.03880787 | I5: 15.407098 | J5: 19 | K5: 3 | L5: 칠곡 | M5: 0.079780093 | N5: 14.989119
A6: 4 | B6: 4 | C6: 구미 | D6: 0.039918981 | E6: 14.978255 | F6: 4 | G6: 경산 | H6: 0.039502315 | I6: 15.136244 | J6: 10 | K6: 4 | L6: 경산 | M6: 0.079814815 | N6: 14.982599
A7: 5 | B7: 5 | C7: 경산 | D7: 0.0403125 | E7: 14.832041 | F7: 5 | G7: 영주 | H7: 0.039895833 | I7: 14.986945 | J7: 8 | K7: 5 | L7: 상주 | M7: 0.082291667 | N7: 14.531646
A8: 6 | B8: 6 | C8: 칠곡 | D8: 0.040972222 | E8: 14.59322 | F8: 6 | G8: 안동 | H8: 0.040243056 | I8: 14.857636 | J8: 17 | K8: 6 | L8: 고령 | M8: 0.082384259 | N8: 14.515313
A9: 7 | B9: 7 | C9: 경주 | D9: 0.041851852 | E9: 14.286504 | F9: 7 | G9: 문경 | H9: 0.040358796 | I9: 14.815027 | J9: 9 | K9: 7 | L9: 문경 | M9: 0.082604167 | N9: 14.476671
A10: 8 | B10: 8 | C10: 문경 | D10: 0.04224537 | E10: 14.153425 | F10: 8 | G10: 김천 | H10: 0.040752315 | I10: 14.671968 | J10: 2 | K10: 8 | L10: 경주 | M10: 0.082662037 | N10: 14.466536
A11: 9 | B11: 9 | C11: 포항 | D11: 0.0425 | E11: 14.068627 | F11: 9 | G11: 경주 | H11: 0.040810185 | I11: 14.651163 | J11: 7 | K11: 9 | L11: 영천 | M11: 0.08275463 | N11: 14.45035
A12: 10 | B12: 10 | C12: 상주 | D12: 0.043530093 | E12: 13.735709 | F12: 10 | G12: 포항 | H12: 0.04099537 | I12: 14.58498 | J12: 1 | K12: 10 | L12: 포항 | M12: 0.08349537 | N12: 14.322151
A13: 11 | B13: 11 | C13: 안동 | D13: 0.043935185 | E13: 13.609062 | F13: 11 | G13: 영덕 | H13: 0.041145833 | I13: 14.531646 | J13: 4 | K13: 11 | L13: 안동 | M13: 0.084178241 | N13: 14.205967
A14: 12 | B14: 12 | C14: 예천 | D14: 0.045092593 | E14: 13.259754 | F14: 12 | G14: 고령 | H14: 0.042638889 | I14: 14.022801 | J14: 3 | K14: 12 | L14: 김천 | M14: 0.089050926 | N14: 13.428646
... A24: 22 | B24: 22 | C24: 청송 | D24: 0.052962963 | E24: 11.289336 | F24: 22 | G24: 의성 | H24: 0.051643519 | I24: 11.577768 | J24: 12 | K24: 22 | L24: 의성 | M24: 0.10143519 | N24: 11.789137
A25: 23 | B25: 23 | C25: 0 | D25: 0 | E25: 0 | F25: 23 | G25: 0 | H25: 0 | I25: 0 | J25: 23
B27: 초등구간거리 | D27: =[3]초등부자료입력!$C$1 -> 14.35 | F27: 중등구간거리 | H27: =[4]중등부자료입력!$C$1 -> 14.35 | K27: 총구간거리 | M27: =D27+H27 -> 28.7
B30: 1.복사할 면 시트보호후 전체를 복사 함 2.붙여넣을 면에 " 붙여넣기" 선택

Sheet 초등부
A1: 총구간거리 | C1: 15.3 | D1: 100 | E1: 구 간 마 라 톤 대 회 (초 등 부)
A2: 구간 소속 | D2: 포항 | E2: 경주 | F2: 김천 | G2: 안동 | H2: 구미 | I2: 영주 | J2: 영천 | K2: 상주 | L2: 문경 | M2: 경산 | N2: 군위 | O2: 의성 | P2: 청송 | Q2: 영양 | R2: 영덕 | S2: 청도 | T2: 고령 | U2: 성주 | V2: 칠곡 | W2: 예천 | X2: 봉화 | Y2: 울진 | Z2: 울릉
B3: 동시 출발 | C3: 넘 버 | D3: 1-1 | E3: 2-1 | F3: 3-1 | G3: 4-1 | H3: 5-1 | I3: 6-1 | J3: 7-1 | K3: 8-1 | L3: 9-1 | M3: 10-1 | N3: 0 | O3: 11-1 | P3: 12-1 | Q3: 0 | R3: 14-1 | S3: 15-1 | T3: 16-1 | U3: 17-1 | V3: 18-1 | W3: 19-1 | X3: 20-1 | Y3: 21-1 | Z3: 0
A4: 1소구 | C4: 성 명 | D4: 박기림 | E4: 최승현 | F4: 임준서 | G4: 이동영 | H4: 김유찬 | I4: 우지훈 | J4: 권태린 | K4: 박기원 | L4: 김민현 | M4: 이희승 | N4: 0 | O4: 홍준혁 | P4: 이한걸 | Q4: 0 | R4: 윤승찬 | S4: 김민수 | T4: 장영준 | U4: 홍채준 | V4: 이유건 | W4: 김진우 | X4: 배강호 | Y4: 전승원 | Z4: 0
A7: 2.4 | C7: 1소구기록 | D7: 0.0069675926 | E7: 0.0070486111 | F7: 0.0070717593 | G7: 0.006712963 | H7: 0.0071064815 | I7: 0.0070833333 | J7: 0.0063541667 | K7: 0.0088194444 | L7: 0.0064930556 | M7: 0.0063541667 | N7: 0 | O7: 0.0087962963 | P7: 0.019236111 | Q7: 0 | R7: 0.0075231481 | S7: 0.0067592593 | T7: 0.0067013889 | U7: 0.0071759259 | V7: 0.0069560185 | W7: 0.0068981481 | X7: 0.0084143519 | Y7: 0.0073611111 | Z7: 0
A8: 15.686275 | C8: 1소구등위 | D8: 9 | E8: 10 | F8: 11 | G8: 5 | H8: 13 | I8: 12 | J8: 1(2) | K8: 19 | L8: 3 | M8: 1(2) | O8: 18 | P8: 20 | R8: 16 | S8: 6 | T8: 4 | U8: 14 | V8: 8 | W8: 7 | X8: 17 | Y8: 15
C9: 도착기록 | D9: 0.0069675926 | E9: 0.0070486111 | F9: 0.0070717593 | G9: 0.006712963 | H9: 0.0071064815 | I9: 0.0070833333 | J9: 0.0063541667 | K9: 0.0088194444 | L9: 0.0064930556 | M9: 0.0063541667 | N9: 0 | O9: 0.0087962963 | P9: 0.019236111 | Q9: 0 | R9: 0.0075231481 | S9: 0.0067592593 | T9: 0.0067013889 | U9: 0.0071759259 | V9: 0.0069560185 | W9: 0.0068981481 | X9: 0.0084143519 | Y9: 0.0073611111 | Z9: 0
C10: 종합기록 | D10: 0.0069675926 | E10: 0.0070486111 | F10: 0.0070717593 | G10: 0.006712963 | H10: 0.0071064815 | I10: 0.0070833333 | J10: 0.0063541667 | K10: 0.0088194444 | L10: 0.0064930556 | M10: 0.0063541667 | O10: 0.0087962963 | P10: 0.019236111 | R10: 0.0075231481 | S10: 0.0067592593 | T10: 0.0067013889 | U10: 0.0071759259 | V10: 0.0069560185 | W10: 0.0068981481 | X10: 0.0084143519 | Y10: 0.0073611111
C11: 종합순위 | D11: 9 | E11: 10 | F11: 11 | G11: 5 | H11: 13 | I11: 12 | J11: 1 | K11: 19 | L11: 3 | M11: 1 | O11: 18 | P11: 20 | R11: 16 | S11: 6 | T11: 4 | U11: 14 | V11: 8 | W11: 7 | X11: 17 | Y11: 15
C12: 넘 버 | D12: 1-2 | E12: 2-2 | F12: 3-2 | G12: 4-2 | H12: 5-2 | I12: 6-2 | J12: 7-2 | K12: 8-2 | L12: 9-2 | M12: 10-2 | N12: 0 | O12: 11-2 | P12: 12-2 | Q12: 0 | R12: 14-2 | S12: 15-2 | T12: 16-2 | U12: 17-2 | V12: 18-2 | W12: 19-2 | X12: 20-2 | Y12: 21-2 | Z12: 0
A13: 2소구 | C13: 성 명 | D13: 김기윤 | E13: 이제원 | F13: 김호영 | G13: 최다원 | H13: 배솔우 | I13: 정예준 | J13: 김민준 | K13: 황동재 | L13: 김학민 | M13: 김선우 | N13: 0 | O13: 오규진 | P13: 정덕채 | Q13: 0 | R13: 김진호 | S13: 박종승 | T13: 박종훈 | U13: 남도균 | V13: 최민혁 | W13: 신준석 | X13: 강경모 | Y13: 신지호 | Z13: 0
C14: 동시출발시간 | D14: 0 | E14: 0 | F14: 0 | G14: 0 | H14: 0 | I14: 0 | J14: 0 | K14: 0 | L14: 0 | M14: 0 | N14: 0 | O14: 0 | P14: 0.0096875 | Q14: 0 | R14: 0 | S14: 0 | T14: 0 | U14: 0 | V14: 0 | W14: 0 | X14: 0 | Y14: 0 | Z14: 0
C15: 동시출발차 | D15: 0 | E15: 0 | F15: 0 | G15: 0 | H15: 0 | I15: 0 | J15: 0 | K15: 0 | L15: 0 | M15: 0 | N15: 0 | O15: 0 | P15: 0.0095486111 | Q15: 0 | R15: 0 | S15: 0 | T15: 0 | U15: 0 | V15: 0 | W15: 0 | X15: 0 | Y15: 0 | Z15: 0
A16: 2.6 | B16: 정상 | C16: 2소구기록 | D16: 0.007719907 | E16: 0.006643519 | F16: 0.010069444 | G16: 0.006782407 | H16: 0.006956019 | I16: 0.007106481 | J16: 0.006516204 | K16: 0.007233796 | L16: 0.006712963 | M16: 0.006458333 | N16: 0 | O16: 0.009363426 | P16: 0.009699074 | Q16: 0 | R16: 0.008993056 | S16: 0.00787037 | T16: 0.006770833 | U16: 0.008587963 | V16: 0.007083333 | W16: 0.007372685 | X16: 0.0078125 | Y16: 0.007638889 | Z16: 0
A17: 16.993464 | B17: TRUE | C17: 2소구등위 | D17: 13 | E17: 3 | F17: 20 | G17: 6 | H17: 7 | I17: 9 | J17: 2 | K17: 10 | L17: 4 | M17: 1 | O17: 18 | P17: 19 | R17: 17 | S17: 15 | T17: 5 | U17: 16 | V17: 8 | W17: 11 | X17: 14 | Y17: 12
C18: 도착기록 | D18: 0.0146875 | E18: 0.01369213 | F18: 0.017141204 | G18: 0.01349537 | H18: 0.0140625 | I18: 0.014189815 | J18: 0.01287037 | K18: 0.016053241 | L18: 0.013206019 | M18: 0.0128125 | N18: 0 | O18: 0.018159722 | P18: 0.019386574 | Q18: 0 | R18: 0.016516204 | S18: 0.01462963 | T18: 0.013472222 | U18: 0.015763889 | V18: 0.014039352 | W18: 0.014270833 | X18: 0.016226852 | Y18: 0.015 | Z18: 0
C19: 종합기록 | D19: 0.0146875 | E19: 0.01369213 | F19: 0.017141203 | G19: 0.01349537 | H19: 0.0140625 | I19: 0.014189814 | J19: 0.012870371 | K19: 0.01605324 | L19: 0.013206019 | M19: 0.0128125 | O19: 0.018159722 | P19: 0.028935185 | R19: 0.016516204 | S19: 0.014629629 | T19: 0.013472222 | U19: 0.015763889 | V19: 0.014039352 | W19: 0.014270833 | X19: 0.016226852 | Y19: 0.015
C20: 종합순위 | D20: 12 | E20: 6 | F20: 18 | G20: 5 | H20: 8 | I20: 9 | J20: 2 | K20: 15 | L20: 3 | M20: 1 | O20: 19 | P20: 20 | R20: 17 | S20: 11 | T20: 4 | U20: 14 | V20: 7 | W20: 10 | X20: 16 | Y20: 13
C21: 넘 버 | D21: 1-3 | E21: 2-3 | F21: 3-3 | G21: 4-3 | H21: 5-3 | I21: 6-3 | J21: 7-3 | K21: 8-3 | L21: 9-3 | M21: 10-3 | N21: 0 | O21: 11-3 | P21: 12-3 | Q21: 0 | R21: 14-3 | S21: 15-3 | T21: 16-3 | U21: 17-3 | V21: 18-3 | W21: 19-3 | X21: 20-3 | Y21: 21-3 | Z21: 0
A22: 3소구 | C22: 성 명 | D22: 구하은 | E22: 전지희 | F22: 조예슬 | G22: 송재연 | H22: 유나래 | I22: 김가희 | J22: 정윤서 | K22: 김단아 | L22: 김유리 | M22: 이희명 | N22: 0 | O22: 김서윤 | P22: 정민선 | Q22: 0 | R22: 최서연 | S22: 장해솔 | T22: 노현정 | U22: 임수진 | V22: 장여진 | W22: 한유진 | X22: 김나예 | Y22: 박서영 | Z22: 0
C23: 동시출발시간 | D23: 0 | E23: 0 | F23: 0.015763889 | G23: 0 | H23: 0 | I23: 0 | J23: 0 | K23: 0.015763889 | L23: 0 | M23: 0 | N23: 0 | O23: 0.015763889 | P23: 0.015763889 | Q23: 0 | R23: 0.015763889 | S23: 0 | T23: 0 | U23: 0 | V23: 0 | W23: 0 | X23: 0.015763889 | Y23: 0 | Z23: 0
C24: 동시출발차 | D24: 0 | E24: 0 | F24: 0.0013773148 | G24: 0 | H24: 0 | I24: 0 | J24: 0 | K24: 0.00028935185 | L24: 0 | M24: 0 | N24: 0 | O24: 0.0023958333 | P24: 0.0036226852 | Q24: 0 | R24: 0.00075231481 | S24: 0 | T24: 0 | U24: 0 | V24: 0 | W24: 0 | X24: 0.00046296296 | Y24: 0 | Z24: 0
A25: 2.3 | B25: 정상 | C25: 3소구기록 | D25: 0.006458333 | E25: 0.006793981 | F25: 0.007372685 | G25: 0.006365741 | H25: 0.008101852 | I25: 0.007013889 | J25: 0.00724537 | K25: 0.00787037 | L25: 0.006747685 | M25: 0.007395833 | N25: 0 | O25: 0.008831019 | P25: 0.009282407 | Q25: 0 | R25: 0.009618056 | S25: 0.007118056 | T25: 0.006886574 | U25: 0.008761574 | V25: 0.007638889 | W25: 0.007916667 | X25: 0.00869213 | Y25: 0.007013889 | Z25: 0
A26: 15.03268 | B26: TRUE | C26: 3소구등위 | D26: 2 | E26: 4 | F26: 10 | G26: 1 | H26: 15 | I26: 6(2) | J26: 9 | K26: 13 | L26: 3 | M26: 11 | O26: 18 | P26: 19 | R26: 20 | S26: 8 | T26: 5 | U26: 17 | V26: 12 | W26: 14 | X26: 16 | Y26: 6(2)
C27: 도착기록 | D27: 0.021145833 | E27: 0.020486111 | F27: 0.023136574 | G27: 0.019861111 | H27: 0.022164352 | I27: 0.021203704 | J27: 0.020115741 | K27: 0.023634259 | L27: 0.019953704 | M27: 0.020208333 | N27: 0 | O27: 0.024594907 | P27: 0.025046296 | Q27: 0 | R27: 0.025381944 | S27: 0.021747685 | T27: 0.020358796 | U27: 0.024525463 | V27: 0.021678241 | W27: 0.0221875 | X27: 0.024456019 | Y27: 0.022013889 | Z27: 0
C28: 종합기록 | D28: 0.021145833 | E28: 0.020486111 | F28: 0.024513888 | G28: 0.019861111 | H28: 0.022164352 | I28: 0.021203703 | J28: 0.020115741 | K28: 0.02392361 | L28: 0.019953704 | M28: 0.020208333 | O28: 0.026990741 | P28: 0.038217592 | R28: 0.02613426 | S28: 0.021747685 | T28: 0.020358796 | U28: 0.024525463 | V28: 0.021678241 | W28: 0.0221875 | X28: 0.024918982 | Y28: 0.022013889
C29: 종합순위 | D29: 7 | E29: 6 | F29: 15 | G29: 1 | H29: 12 | I29: 8 | J29: 3 | K29: 14 | L29: 2 | M29: 4 | O29: 19 | P29: 20 | R29: 18 | S29: 10 | T29: 5 | U29: 16 | V29: 9 | W29: 13 | X29: 17 | Y29: 11
C30: 넘 버 | D30: 1-4 | E30: 2-4 | F30: 3-4 | G30: 4-4 | H30: 5-4 | I30: 6-4 | J30: 7-4 | K30: 8-4 | L30: 9-4 | M30: 10-4 | N30: 0 | O30: 11-4 | P30: 12-4 | Q30: 0 | R30: 14-4 | S30: 15-4 | T30: 16-4 | U30: 17-4 | V30: 18-4 | W30: 19-4 | X30: 20-4 | Y30: 21-4 | Z30: 0
A31: 4소구 | C31: 성 명 | D31: 김지아 | E31: 김혜령 | F31: 임채은 | G31: 조은비 | H31: 이지수 | I31: 전수빈 | J31: 이윤아 | K31: 김예진 | L31: 김수민 | M31: 박주예 | N31: 0 | O31: 오수빈 | P31: 구다윤 | Q31: 0 | R31: 김나연 | S31: 박예윤 | T31: 허재은 | U31: 신윤아 | V31: 이진아 | W31: 금소윤 | X31: 김예서 | Y31: 이수인 | Z31: 0
C32: 동시출발시간 | D32: 0 | E32: 0 | F32: 0 | G32: 0 | H32: 0 | I32: 0 | J32: 0 | K32: 0 | L32: 0 | M32: 0 | N32: 0 | O32: 0 | P32: 0 | Q32: 0 | R32: 0 | S32: 0 | T32: 0 | U32: 0 | V32: 0 | W32: 0 | X32: 0 | Y32: 0 | Z32: 0
C33: 동시출발차 | D33: 0 | E33: 0 | F33: 0 | G33: 0 | H33: 0 | I33: 0 | J33: 0 | K33: 0 | L33: 0 | M33: 0 | N33: 0 | O33: 0 | P33: 0 | Q33: 0 | R33: 0 | S33: 0 | T33: 0 | U33: 0 | V33: 0 | W33: 0 | X33: 0 | Y33: 0 | Z33: 0
A34: 1.8 | B34: 정상 | C34: 4소구기록 | D34: 0.004988426 | E34: 0.005763889 | F34: 0.007418981 | G34: 0.005810185 | H34: 0.005972222 | I34: 0.006319444 | J34: 0.005231481 | K34: 0.006701389 | L34: 0.005856481 | M34: 0.005277778 | N34: 0 | O34: 0.006168981 | P34: 0.007592593 | Q34: 0 | R34: 0.007673611 | S34: 0.006539352 | T34: 0.004768519 | U34: 0.006261574 | V34: 0.006226852 | W34: 0.005891204 | X34: 0.006273148 | Y34: 0.006319444 | Z34: 0
A35: 11.764706 | B35: TRUE | C35: 4소구등위 | D35: 2 | E35: 5 | F35: 18 | G35: 6 | H35: 9 | I35: 14(2) | J35: 3 | K35: 17 | L35: 7 | M35: 4 | O35: 10 | P35: 19 | R35: 20 | S35: 16 | T35: 1 | U35: 12 | V35: 11 | W35: 8 | X35: 13 | Y35: 14(2)
C36: 도착기록 | D36: 0.026134259 | E36: 0.02625 | F36: 0.030555556 | G36: 0.025671296 | H36: 0.028136574 | I36: 0.027523148 | J36: 0.025347222 | K36: 0.030335648 | L36: 0.025810185 | M36: 0.025486111 | N36: 0 | O36: 0.030763889 | P36: 0.032638889 | Q36: 0 | R36: 0.033055556 | S36: 0.028287037 | T36: 0.025127315 | U36: 0.030787037 | V36: 0.027905093 | W36: 0.028078704 | X36: 0.030729167 | Y36: 0.028333333 | Z36: 0
C37: 종합기록 | D37: 0.026134259 | E37: 0.02625 | F37: 0.031932869 | G37: 0.025671296 | H37: 0.028136574 | I37: 0.027523147 | J37: 0.025347222 | K37: 0.030624999 | L37: 0.025810185 | M37: 0.025486111 | O37: 0.033159722 | P37: 0.045810185 | R37: 0.033807871 | S37: 0.028287037 | T37: 0.025127315 | U37: 0.030787037 | V37: 0.027905093 | W37: 0.028078704 | X37: 0.03119213 | Y37: 0.028333333
C38: 종합순위 | D38: 6 | E38: 7 | F38: 17 | G38: 4 | H38: 11 | I38: 8 | J38: 2 | K38: 14 | L38: 5 | M38: 3 | O38: 18 | P38: 20 | R38: 19 | S38: 12 | T38: 1 | U38: 15 | V38: 9 | W38: 10 | X38: 16 | Y38: 13
C39: 넘 버 | D39: 1-5 | E39: 2-5 | F39: 3-5 | G39: 4-5 | H39: 5-5 | I39: 6-5 | J39: 7-5 | K39: 8-5 | L39: 9-5 | M39: 10-5 | N39: 0 | O39: 11-5 | P39: 12-5 | Q39: 0 | R39: 14-5 | S39: 15-5 | T39: 16-5 | U39: 17-5 | V39: 18-5 | W39: 19-5 | X39: 20-5 | Y39: 21-5 | Z39: 0
A40: 5소구 | C40: 성 명 | D40: 김도현 | E40: 조승재 | F40: 박휘건 | G40: 권경도 | H40: 김동현 | I40: 신명식 | J40: 박건하 | K40: 김하람 | L40: 김재환 | M40: 성채호 | N40: 0 | O40: 오승민 | P40: 김수환 | Q40: 0 | R40: 윤승우 | S40: 박시후 | T40: 윤강우 | U40: 김강민 | V40: 이율 | W40: 김이언 | X40: 황예준 | Y40: 박주영 | Z40: 0
C41: 동시출발시간 | D41: 0 | E41: 0 | F41: 0 | G41: 0 | H41: 0 | I41: 0 | J41: 0 | K41: 0 | L41: 0 | M41: 0 | N41: 0 | O41: 0 | P41: 0 | Q41: 0 | R41: 0 | S41: 0 | T41: 0 | U41: 0 | V41: 0 | W41: 0 | X41: 0 | Y41: 0 | Z41: 0
C42: 동시출발차 | D42: 0 | E42: 0 | F42: 0 | G42: 0 | H42: 0 | I42: 0 | J42: 0 | K42: 0 | L42: 0 | M42: 0 | N42: 0 | O42: 0 | P42: 0 | Q42: 0 | R42: 0 | S42: 0 | T42: 0 | U42: 0 | V42: 0 | W42: 0 | X42: 0 | Y42: 0 | Z42: 0
...

Sheet 중등부
A1: 총구간거리 | C1: 15.3 | D1: 100 | E1: 구 간 마 라 톤 대 회 (중 등 부)
A2: 구간 소속 | D2: 포항 | E2: 경주 | F2: 김천 | G2: 안동 | H2: 구미 | I2: 영주 | J2: 영천 | K2: 상주 | L2: 문경 | M2: 경산 | N2: 군위 | O2: 의성 | P2: 청송 | Q2: 영양 | R2: 영덕 | S2: 청도 | T2: 고령 | U2: 성주 | V2: 칠곡 | W2: 예천 | X2: 봉화 | Y2: 울진 | Z2: 울릉
B3: 동시 출발 | C3: 넘 버 | D3: 1-1 | E3: 2-1 | F3: 3-1 | G3: 4-1 | H3: 5-1 | I3: 6-1 | J3: 7-1 | K3: 8-1 | L3: 9-1 | M3: 10-1 | N3: 0 | O3: 11-1 | P3: 12-1 | Q3: 13-1 | R3: 14-1 | S3: 15-1 | T3: 16-1 | U3: 17-1 | V3: 18-1 | W3: 19-1 | X3: 20-1 | Y3: 21-1 | Z3: 0
A4: 1소구 | C4: 성 명 | D4: 최아이린 | E4: 안령경 | F4: 김민서 | G4: 권현진 | H4: 이소진 | I4: 윤현주 | J4: 송다원 | K4: 이선경 | L4: 양은지 | M4: 조서연 | N4: 0 | O4: 남경애 | P4: 윤은주 | Q4: 박한서 | R4: 박성은 | S4: 박예담 | T4: 권수빈 | U4: 박정민 | V4: 우정민 | W4: 박예원 | X4: 이소윤 | Y4: 손예은 | Z4: 0
D5: FALSE
A7: 2.4 | C7: 1소구기록 | D7: 0.008125 | E7: 0.0065277778 | F7: 0.0074189815 | G7: 0.0065972222 | H7: 0.0079861111 | I7: 0.0083217593 | J7: 0.0059953704 | K7: 0.0072453704 | L7: 0.0076157407 | M7: 0.0071180556 | N7: 0 | O7: 0.0088078704 | P7: 0.0084722222 | Q7: 0.0093287037 | R7: 0.010173611 | S7: 0.0087615741 | T7: 0.0099537037 | U7: 0.0093171296 | V7: 0.0079166667 | W7: 0.0086574074 | X7: 0.0078472222 | Y7: 0.0096412037 | Z7: 0
A8: 15.686275 | C8: 1소구등위 | D8: 11 | E8: 2 | F8: 6 | G8: 3 | H8: 10 | I8: 12 | J8: 1 | K8: 5 | L8: 7 | M8: 4 | O8: 16 | P8: 13 | Q8: 18 | R8: 21 | S8: 15 | T8: 20 | U8: 17 | V8: 9 | W8: 14 | X8: 8 | Y8: 19
C9: 도착기록 | D9: 0.008125 | E9: 0.0065277778 | F9: 0.0074189815 | G9: 0.0065972222 | H9: 0.0079861111 | I9: 0.0083217593 | J9: 0.0059953704 | K9: 0.0072453704 | L9: 0.0076157407 | M9: 0.0071180556 | N9: 0 | O9: 0.0088078704 | P9: 0.0084722222 | Q9: 0.0093287037 | R9: 0.010173611 | S9: 0.0087615741 | T9: 0.0099537037 | U9: 0.0093171296 | V9: 0.0079166667 | W9: 0.0086574074 | X9: 0.0078472222 | Y9: 0.0096412037 | Z9: 0
C10: 종합기록 | D10: 0.008125 | E10: 0.0065277778 | F10: 0.0074189815 | G10: 0.0065972222 | H10: 0.0079861111 | I10: 0.0083217593 | J10: 0.0059953704 | K10: 0.0072453704 | L10: 0.0076157407 | M10: 0.0071180556 | O10: 0.0088078704 | P10: 0.0084722222 | Q10: 0.0093287037 | R10: 0.010173611 | S10: 0.0087615741 | T10: 0.0099537037 | U10: 0.0093171296 | V10: 0.0079166667 | W10: 0.0086574074 | X10: 0.0078472222 | Y10: 0.0096412037
C11: 종합순위 | D11: 11 | E11: 2 | F11: 6 | G11: 3 | H11: 10 | I11: 12 | J11: 1 | K11: 5 | L11: 7 | M11: 4 | O11: 16 | P11: 13 | Q11: 18 | R11: 21 | S11: 15 | T11: 20 | U11: 17 | V11: 9 | W11: 14 | X11: 8 | Y11: 19
C12: 넘 버 | D12: 1-2 | E12: 2-2 | F12: 3-2 | G12: 4-2 | H12: 5-2 | I12: 6-2 | J12: 7-2 | K12: 8-2 | L12: 9-2 | M12: 10-2 | N12: 0 | O12: 11-2 | P12: 12-2 | Q12: 13-2 | R12: 14-2 | S12: 15-2 | T12: 16-2 | U12: 17-2 | V12: 18-2 | W12: 19-2 | X12: 20-2 | Y12: 21-2 | Z12: 0
A13: 2소구 | C13: 성 명 | D13: 김현우 | E13: 백금동 | F13: 김세빈 | G13: 김혜동 | H13: 신재효 | I13: 권오을 | J13: 염승수 | K13: 이준혁 | L13: 지준서 | M13: 전형준 | N13: 0 | O13: 김탁경 | P13: 김건섭 | Q13: 김현서 | R13: 임기민 | S13: 박종민 | T13: 이재윤 | U13: 김동해 | V13: 이종철 | W13: 장민성 | X13: 고경민 | Y13: 정재환 | Z13: 0
C14: 동시출발시간 | D14: 0 | E14: 0 | F14: 0 | G14: 0 | H14: 0 | I14: 0 | J14: 0 | K14: 0 | L14: 0 | M14: 0 | N14: 0 | O14: 0 | P14: 0 | Q14: 0 | R14: 0 | S14: 0 | T14: 0 | U14: 0 | V14: 0 | W14: 0 | X14: 0 | Y14: 0 | Z14: 0
C15: 동시출발차 | D15: 0 | E15: 0 | F15: 0 | G15: 0 | H15: 0 | I15: 0 | J15: 0 | K15: 0 | L15: 0 | M15: 0 | N15: 0 | O15: 0 | P15: 0 | Q15: 0 | R15: 0 | S15: 0 | T15: 0 | U15: 0 | V15: 0 | W15: 0 | X15: 0 | Y15: 0 | Z15: 0
A16: 2.9 | B16: 정상 | C16: 2소구기록 | D16: 0.008356481 | E16: 0.006724537 | F16: 0.008194444 | G16: 0.007314815 | H16: 0.007719907 | I16: 0.007025463 | J16: 0.007453704 | K16: 0.007523148 | L16: 0.007418981 | M16: 0.00630787 | N16: 0 | O16: 0.007337963 | P16: 0.008645833 | Q16: 0.008113426 | R16: 0.008483796 | S16: 0.008912037 | T16: 0.008703704 | U16: 0.009421296 | V16: 0.007534722 | W16: 0.008032407 | X16: 0.008831019 | Y16: 0.009016204 | Z16: 0
A17: 18.954248 | B17: TRUE | C17: 2소구등위 | D17: 14 | E17: 2 | F17: 13 | G17: 4 | H17: 10 | I17: 3 | J17: 7 | K17: 8 | L17: 6 | M17: 1 | O17: 5 | P17: 16 | Q17: 12 | R17: 15 | S17: 19 | T17: 17 | U17: 21 | V17: 9 | W17: 11 | X17: 18 | Y17: 20
C18: 도착기록 | D18: 0.016481481 | E18: 0.013252315 | F18: 0.015613426 | G18: 0.013912037 | H18: 0.015706019 | I18: 0.015347222 | J18: 0.013449074 | K18: 0.014768519 | L18: 0.015034722 | M18: 0.013425926 | N18: 0 | O18: 0.016145833 | P18: 0.017118056 | Q18: 0.01744213 | R18: 0.018657407 | S18: 0.017673611 | T18: 0.018657407 | U18: 0.018738426 | V18: 0.015451389 | W18: 0.016689815 | X18: 0.016678241 | Y18: 0.018657407 | Z18: 0
C19: 종합기록 | D19: 0.016481481 | E19: 0.013252315 | F19: 0.015613425 | G19: 0.013912037 | H19: 0.015706018 | I19: 0.015347222 | J19: 0.013449074 | K19: 0.014768518 | L19: 0.015034722 | M19: 0.013425926 | O19: 0.016145833 | P19: 0.017118055 | Q19: 0.01744213 | R19: 0.018657407 | S19: 0.017673611 | T19: 0.018657408 | U19: 0.018738426 | V19: 0.015451389 | W19: 0.016689814 | X19: 0.016678241 | Y19: 0.018657408
C20: 종합순위 | D20: 12 | E20: 1 | F20: 9 | G20: 4 | H20: 10 | I20: 7 | J20: 3 | K20: 5 | L20: 6 | M20: 2 | O20: 11 | P20: 15 | Q20: 16 | R20: 18 | S20: 17 | T20: 19 | U20: 21 | V20: 8 | W20: 14 | X20: 13 | Y20: 19
C21: 넘 버 | D21: 1-3 | E21: 2-3 | F21: 3-3 | G21: 4-3 | H21: 5-3 | I21: 6-3 | J21: 7-3 | K21: 8-3 | L21: 9-3 | M21: 10-3 | N21: 0 | O21: 11-3 | P21: 12-3 | Q21: 13-3 | R21: 14-3 | S21: 15-3 | T21: 16-3 | U21: 17-3 | V21: 18-3 | W21: 19-3 | X21: 20-3 | Y21: 21-3 | Z21: 0
A22: 3소구 | C22: 성 명 | D22: 김나현 | E22: 김려원 | F22: 김명지 | G22: 김소원 | H22: 이승연 | I22: 윤재영 | J22: 황재희 | K22: 이보민 | L22: 이은솔 | M22: 정다혜 | N22: 0 | O22: 이다해 | P22: 이세린 | Q22: 배채윤 | R22: 류민희 | S22: 박나겸 | T22: 성이정 | U22: 장수민 | V22: 임나연 | W22: 최수영 | X22: 장효민 | Y22: 최여진 | Z22: 0
C23: 동시출발시간 | D23: 0 | E23: 0 | F23: 0 | G23: 0 | H23: 0 | I23: 0 | J23: 0 | K23: 0 | L23: 0 | M23: 0 | N23: 0 | O23: 0 | P23: 0 | Q23: 0 | R23: 0 | S23: 0 | T23: 0 | U23: 0 | V23: 0 | W23: 0 | X23: 0 | Y23: 0 | Z23: 0
C24: 동시출발차 | D24: 0 | E24: 0 | F24: 0 | G24: 0 | H24: 0 | I24: 0 | J24: 0 | K24: 0 | L24: 0 | M24: 0 | N24: 0 | O24: 0 | P24: 0 | Q24: 0 | R24: 0 | S24: 0 | T24: 0 | U24: 0 | V24: 0 | W24: 0 | X24: 0 | Y24: 0 | Z24: 0
A25: 2.6 | B25: 정상 | C25: 3소구기록 | D25: 0.009490741 | E25: 0.008472222 | F25: 0.008194444 | G25: 0.007905093 | H25: 0.009571759 | I25: 0.008368056 | J25: 0.007696759 | K25: 0.00869213 | L25: 0.00837963 | M25: 0.008275463 | N25: 0 | O25: 0.010034722 | P25: 0.011481481 | Q25: 0.010520833 | R25: 0.010092593 | S25: 0.009803241 | T25: 0.01005787 | U25: 0.008946759 | V25: 0.008796296 | W25: 0.009814815 | X25: 0.009074074 | Y25: 0.010115741 | Z25: 0
A26: 16.993464 | B26: TRUE | C26: 3소구등위 | D26: 12 | E26: 7 | F26: 3 | G26: 2 | H26: 13 | I26: 5 | J26: 1 | K26: 8 | L26: 6 | M26: 4 | O26: 16 | P26: 21 | Q26: 20 | R26: 18 | S26: 14 | T26: 17 | U26: 10 | V26: 9 | W26: 15 | X26: 11 | Y26: 19
C27: 도착기록 | D27: 0.025972222 | E27: 0.021724537 | F27: 0.02380787 | G27: 0.02181713 | H27: 0.025277778 | I27: 0.023715278 | J27: 0.021145833 | K27: 0.023460648 | L27: 0.023414352 | M27: 0.021701389 | N27: 0 | O27: 0.026180556 | P27: 0.028599537 | Q27: 0.027962963 | R27: 0.02875 | S27: 0.027476852 | T27: 0.028715278 | U27: 0.027685185 | V27: 0.024247685 | W27: 0.02650463 | X27: 0.025752315 | Y27: 0.028773148 | Z27: 0
C28: 종합기록 | D28: 0.025972222 | E28: 0.021724537 | F28: 0.023807869 | G28: 0.02181713 | H28: 0.025277777 | I28: 0.023715278 | J28: 0.021145833 | K28: 0.023460648 | L28: 0.023414352 | M28: 0.021701389 | O28: 0.026180555 | P28: 0.028599536 | Q28: 0.027962963 | R28: 0.02875 | S28: 0.027476852 | T28: 0.028715278 | U28: 0.027685185 | V28: 0.024247685 | W28: 0.026504629 | X28: 0.025752315 | Y28: 0.028773149
C29: 종합순위 | D29: 12 | E29: 3 | F29: 8 | G29: 4 | H29: 10 | I29: 7 | J29: 1 | K29: 6 | L29: 5 | M29: 2 | O29: 13 | P29: 18 | Q29: 17 | R29: 20 | S29: 15 | T29: 19 | U29: 16 | V29: 9 | W29: 14 | X29: 11 | Y29: 21
C30: 넘 버 | D30: 1-4 | E30: 2-4 | F30: 3-4 | G30: 4-4 | H30: 5-4 | I30: 6-4 | J30: 7-4 | K30: 8-4 | L30: 9-4 | M30: 10-4 | N30: 0 | O30: 11-4 | P30: 12-4 | Q30: 13-4 | R30: 14-4 | S30: 15-4 | T30: 16-4 | U30: 17-4 | V30: 18-4 | W30: 19-4 | X30: 20-4 | Y30: 21-4 | Z30: 0
A31: 4소구 | C31: 성 명 | D31: 탁정호 | E31: 왕현빈 | F31: 전호진 | G31: 최현호 | H31: 조윤혁 | I31: 안병현 | J31: 조준영 | K31: 서유현 | L31: 권재윤 | M31: 김지헌 | N31: 0 | O31: 우지민 | P31: 박천범 | Q31: 정이준 | R31: 박다훈 | S31: 박지민 | T31: 도지완 | U31: 김시원 | V31: 김진욱 | W31: 윤무열 | X31: 안찬민 | Y31: 양준경 | Z31: 0
C32: 동시출발시간 | D32: 0 | E32: 0 | F32: 0 | G32: 0 | H32: 0 | I32: 0 | J32: 0 | K32: 0 | L32: 0 | M32: 0 | N32: 0 | O32: 0 | P32: 0 | Q32: 0 | R32: 0 | S32: 0 | T32: 0 | U32: 0 | V32: 0 | W32: 0 | X32: 0 | Y32: 0 | Z32: 0
C33: 동시출발차 | D33: 0 | E33: 0 | F33: 0 | G33: 0 | H33: 0 | I33: 0 | J33: 0 | K33: 0 | L33: 0 | M33: 0 | N33: 0 | O33: 0 | P33: 0 | Q33: 0 | R33: 0 | S33: 0 | T33: 0 | U33: 0 | V33: 0 | W33: 0 | X33: 0 | Y33: 0 | Z33: 0
A34: 3.1 | B34: 정상 | C34: 4소구기록 | D34: 0.009166667 | E34: 0.007291667 | F34: 0.009918981 | G34: 0.008518519 | H34: 0.00806713 | I34: 0.008715278 | J34: 0.008159722 | K34: 0.008240741 | L34: 0.007743056 | M34: 0.007824074 | N34: 0 | O34: 0.007719907 | P34: 0.010891204 | Q34: 0.009479167 | R34: 0.009502315 | S34: 0.008310185 | T34: 0.00912037 | U34: 0.009178241 | V34: 0.007847222 | W34: 0.009398148 | X34: 0.009456019 | Y34: 0.009236111 | Z34: 0
A35: 20.261438 | B35: TRUE | C35: 4소구등위 | D35: 13 | E35: 1 | F35: 20 | G35: 10 | H35: 6 | I35: 11 | J35: 7 | K35: 8 | L35: 3 | M35: 4 | O35: 2 | P35: 21 | Q35: 18 | R35: 19 | S35: 9 | T35: 12 | U35: 14 | V35: 5 | W35: 16 | X35: 17 | Y35: 15
C36: 도착기록 | D36: 0.035138889 | E36: 0.029016204 | F36: 0.033726852 | G36: 0.030335648 | H36: 0.033344907 | I36: 0.032430556 | J36: 0.029305556 | K36: 0.031701389 | L36: 0.031157407 | M36: 0.029525463 | N36: 0 | O36: 0.033900463 | P36: 0.039490741 | Q36: 0.03744213 | R36: 0.038252315 | S36: 0.035787037 | T36: 0.037835648 | U36: 0.036863426 | V36: 0.032094907 | W36: 0.035902778 | X36: 0.035208333 | Y36: 0.038009259 | Z36: 0
C37: 종합기록 | D37: 0.035138889 | E37: 0.029016204 | F37: 0.03372685 | G37: 0.030335649 | H37: 0.033344907 | I37: 0.032430556 | J37: 0.029305555 | K37: 0.031701389 | L37: 0.031157408 | M37: 0.029525463 | O37: 0.033900462 | P37: 0.03949074 | Q37: 0.03744213 | R37: 0.038252315 | S37: 0.035787037 | T37: 0.037835648 | U37: 0.036863426 | V37: 0.032094907 | W37: 0.035902777 | X37: 0.035208334 | Y37: 0.03800926
C38: 종합순위 | D38: 12 | E38: 1 | F38: 10 | G38: 4 | H38: 9 | I38: 8 | J38: 2 | K38: 6 | L38: 5 | M38: 3 | O38: 11 | P38: 21 | Q38: 17 | R38: 20 | S38: 14 | T38: 18 | U38: 16 | V38: 7 | W38: 15 | X38: 13 | Y38: 19
C39: 넘 버 | D39: 1-5 | E39: 2-5 | F39: 3-5 | G39: 4-5 | H39: 5-5 | I39: 6-5 | J39: 7-5 | K39: 8-5 | L39: 9-5 | M39: 10-5 | N39: 0 | O39: 11-5 | P39: 12-5 | Q39: 13-5 | R39: 14-5 | S39: 15-5 | T39: 16-5 | U39: 17-5 | V39: 18-5 | W39: 19-5 | X39: 20-5 | Y39: 21-5 | Z39: 0
A40: 5소구 | C40: 성 명 | D40: 김지원 | E40: 유채연 | F40: 강세민 | G40: 서주경 | H40: 이휘아 | I40: 김도희 | J40: 김시연 | K40: 윤소영 | L40: 정예주 | M40: 서예림 | N40: 0 | O40: 김한솔 | P40: 안지율 | Q40: 김주연 | R40: 이서연 | S40: 김태경 | T40: 전수빈 | U40: 박현주 | V40: 서민지 | W40: 최은서 | X40: 김윤슬 | Y40: 김보미 | Z40: 0
C41: 동시출발시간 | D41: 0.032430556 | E41: 0 | F41: 0.032430556 | G41: 0 | H41: 0.032430556 | I41: 0 | J41: 0 | K41: 0 | L41: 0 | M41: 0 | N41: 0 | O41: 0.032430556 | P41: 0.032430556 | Q41: 0.032430556 | R41: 0.032430556 | S41: 0.032430556 | T41: 0.032430556 | U41: 0.032430556 | V41: 0 | W41: 0.032430556 | X41: 0.032430556 | Y41: 0.032430556 | Z41: 0
...
